Workbook

Sheet 课堂表现
A1: 《移动应用开发》课堂表现
A2: 学号 | B2: 姓名 | C2: 知识图谱 | D2: TRAE | E2: 原生 | F2: AS | G2: iOS | H2: Typora | I2: 混合 | J2: 小程序 | K2: PUML | L2: 开发计划 | M2: 原始分 | N2: 最后得分
A3: 2020211034 | B3: 张梦杰 | C3: 0 | D3: 0 | E3: 0 | F3: 0 | G3: 0 | H3: 0 | I3: 9 | J3: 0 | K3: 0 | L3: 0 | M3: =SUM(I3:L3) -> 9 | N3: =M3+55 -> 64
A4: 2020213700 | B4: 童其凡 | C4: -10 | D4: 8 | E4: 10 | F4: 9 | G4: 9 | H4: 8 | I4: 9 | J4: 9 | K4: 8 | L4: 0 | M4: =SUM(I4:L4) -> 26 | N4: =M4+55 -> 81
A5: 2022210331 | B5: 曹安晨 | C5: 8 | D5: 8 | E5: 9 | F5: 9 | G5: 9 | H5: 0 | I5: 9 | J5: 9 | K5: 8 | L5: 8 | M5: =SUM(I5:L5) -> 34 | N5: =M5+55 -> 89
A6: 2022210332 | B6: 陈晨 | C6: 8 | D6: 0 | E6: 10 | F6: 9 | G6: 9 | H6: 8 | I6: 9 | J6: 9 | K6: 8 | L6: 8 | M6: =SUM(I6:L6) -> 34 | N6: =M6+55 -> 89
A7: 2022210333 | B7: 陈创东 | C7: 8 | D7: 8 | E7: 9 | F7: 9 | G7: 9 | H7: 8 | I7: 9 | J7: 9 | K7: 0 | L7: 8 | M7: =SUM(I7:L7) -> 26 | N7: =M7+55 -> 81
A8: 2022210334 | B8: 程纪阳 | C8: 8 | D8: 8 | E8: 9 | F8: 9 | G8: 9 | H8: 10 | I8: 9 | J8: 9 | K8: 8 | L8: 8 | M8: =SUM(I8:L8) -> 34 | N8: =M8+55 -> 89
A9: 2022210335 | B9: 程梦圆 | C9: 8 | D9: 8 | E9: 9 | F9: 0 | G9: 9 | H9: 8 | I9: 9 | J9: 9 | K9: 8 | L9: 0 | M9: =SUM(I9:L9) -> 26 | N9: =M9+55 -> 81
A10: 2022210337 | B10: 邓慧茹 | C10: 8 | D10: 8 | E10: 10 | F10: 9 | G10: 9 | H10: 8 | I10: 9 | J10: 9 | K10: 8 | L10: 8 | M10: =SUM(I10:L10) -> 34 | N10: =M10+55 -> 89
A11: 2022210338 | B11: 丁玉耀 | C11: 0 | D11: 0 | E11: 0 | F11: 0 | G11: 0 | H11: 0 | I11: 0 | J11: 0 | K11: 0 | L11: 0 | M11: =SUM(I11:L11) -> 0 | N11: 0
A12: 2022210339 | B12: 范鑫蕊 | C12: 8 | D12: 8 | E12: 10 | F12: 9 | G12: 9 | H12: 8 | I12: 9 | J12: 9 | K12: 8 | L12: 8 | M12: =SUM(I12:L12) -> 34 | N12: =M12+55 -> 89
A13: 2022210342 | B13: 高恩鹏 | C13: 8 | D13: 8 | E13: 9 | F13: 9 | G13: 9 | H13: 8 | I13: 9 | J13: 9 | K13: 8 | L13: 0 | M13: =SUM(I13:L13) -> 26 | N13: =M13+55 -> 81
A14: 2022210343 | B14: 关雪艳 | C14: 8 | D14: 8 | E14: 9 | F14: 9 | G14: 9 | H14: 8 | I14: 9 | J14: 9 | K14: 8 | L14: 8 | M14: =SUM(I14:L14) -> 34 | N14: =M14+55 -> 89
A15: 2022210344 | B15: 郭新杰 | C15: 8 | D15: 8 | E15: 10 | F15: 9 | G15: 9 | H15: 8 | I15: 9 | J15: 9 | K15: 8 | L15: 8 | M15: =SUM(I15:L15) -> 34 | N15: =M15+55 -> 89
A16: 2022210346 | B16: 洪晓瑞 | C16: 8 | D16: 0 | E16: 9 | F16: 9 | G16: 0 | H16: 8 | I16: 9 | J16: 9 | K16: 8 | L16: 0 | M16: =SUM(I16:L16) -> 26 | N16: =M16+55 -> 81
A17: 2022210347 | B17: 胡步兴 | C17: 8 | D17: 8 | E17: 10 | F17: 9 | G17: 9 | H17: 8 | I17: 9 | J17: 9 | K17: 0 | L17: 8 | M17: =SUM(I17:L17) -> 26 | N17: =M17+55 -> 81
A18: 2022210348 | B18: 胡昊泱 | C18: 8 | D18: 8 | E18: 9 | F18: 9 | G18: 0 | H18: 8 | I18: 9 | J18: 9 | K18: 0 | L18: 8 | M18: =SUM(I18:L18) -> 26 | N18: =M18+55 -> 81
A19: 2022210351 | B19: 季玮 | C19: 8 | D19: 8 | E19: 9 | F19: 9 | G19: 0 | H19: 8 | I19: 9 | J19: 9 | K19: 8 | L19: 8 | M19: =SUM(I19:L19) -> 34 | N19: =M19+55 -> 89
A20: 2022210359 | B20: 李宝航 | C20: 0 | D20: 0 | E20: 0 | F20: 0 | G20: 0 | H20: 0 | I20: 0 | J20: 0 | K20: 0 | L20: 0 | M20: =SUM(I20:L20) -> 0 | N20: =M20+55 -> 55
A21: 2022210360 | B21: 李浩 | C21: 8 | D21: 8 | E21: 9 | F21: 9 | G21: 0 | H21: 8 | I21: 9 | J21: 9 | K21: 8 | L21: 8 | M21: =SUM(I21:L21) -> 34 | N21: =M21+55 -> 89
A22: 2022210361 | B22: 李今朝 | C22: 8 | D22: 8 | E22: 9 | F22: 0 | G22: 0 | H22: 0 | I22: 0 | J22: 9 | K22: 8 | L22: 0 | M22: =SUM(I22:L22) -> 17 | N22: =M22+55 -> 72
A23: 2022210362 | B23: 李良辰 | C23: 7 | D23: 8 | E23: 9 | G23: 9 | H23: 0 | I23: 0 | J23: 0 | K23: 0 | L23: 0 | M23: =SUM(I23:L23) -> 0 | N23: =M23+55 -> 55
A24: 2022210367 | B24: 梁平 | C24: 8 | D24: 8 | E24: 9 | F24: 9 | G24: 9 | H24: 0 | I24: 9 | J24: 9 | K24: 8 | L24: 8 | M24: =SUM(I24:L24) -> 34 | N24: =M24+55 -> 89
A25: 2022210371 | B25: 陆征宇 | C25: 8 | D25: 8 | E25: 9 | F25: 9 | G25: 0 | H25: 8 | I25: 9 | J25: 9 | K25: 8 | L25: 0 | M25: =SUM(I25:L25) -> 26 | N25: =M25+55 -> 81
A26: 2022210374 | B26: 苗佳宇 | C26: 8 | D26: 8 | E26: 9 | F26: 9 | G26: 9 | H26: 8 | I26: 9 | J26: 9 | K26: 8 | L26: 8 | M26: =SUM(I26:L26) -> 34 | N26: =M26+55 -> 89
A27: 2022210376 | B27: 庞雨俊 | C27: 0 | D27: 0 | E27: 0 | F27: 0 | G27: 0 | H27: 0 | I27: 0 | J27: 0 | K27: 8 | L27: 0 | M27: =SUM(I27:L27) -> 8 | N27: =M27+55 -> 63
A28: 2022210378 | B28: 戚锐 | C28: 8 | D28: 8 | E28: 10 | F28: 9 | G28: 9 | H28: 8 | I28: 9 | J28: 9 | K28: 0 | L28: 8 | M28: =SUM(I28:L28) -> 26 | N28: =M28+55 -> 81
A29: 2022210380 | B29: 任奕凯 | C29: 8 | D29: 8 | E29: 10 | F29: 9 | G29: 9 | H29: 10 | I29: 9 | J29: 9 | K29: 8 | L29: 8 | M29: =SUM(I29:L29) -> 34 | N29: =M29+55 -> 89
A30: 2022210381 | B30: 阮珧 | C30: 8 | D30: 0 | E30: 0 | F30: 0 | G30: 9 | H30: 0 | I30: 9 | J30: 0 | K30: 0 | L30: 0 | M30: =SUM(I30:L30) -> 9 | N30: =M30+55 -> 64
A31: 2022210384 | B31: 孙嘉婧 | C31: 8 | D31: 8 | E31: 9 | F31: 9 | G31: 9 | H31: 0 | I31: 9 | J31: 9 | K31: 8 | L31: 0 | M31: =SUM(I31:L31) -> 26 | N31: =M31+55 -> 81
A32: 2022210385 | B32: 孙锦年 | C32: 8 | D32: 0 | E32: 9 | F32: 9 | G32: 9 | H32: 8 | I32: 9 | J32: 9 | K32: 0 | L32: 0 | M32: =SUM(I32:L32) -> 18 | N32: =M32+55 -> 73
A33: 2022210387 | B33: 唐蕊 | C33: 8 | D33: 8 | E33: 0 | F33: 9 | G33: 0 | H33: 10 | I33: 9 | J33: 9 | K33: 0 | L33: 8 | M33: =SUM(I33:L33) -> 26 | N33: =M33+55 -> 81
A34: 2022210389 | B34: 汪海洋 | C34: 8 | D34: 8 | E34: 9 | F34: 9 | G34: 0 | H34: 8 | I34: 0 | J34: 9 | K34: 8 | L34: 8 | M34: =SUM(I34:L34) -> 25 | N34: =M34+55 -> 80
A35: 2022210392 | B35: 王瑞 | C35: 8 | D35: 8 | E35: 9 | F35: 9 | G35: 9 | H35: 8 | I35: 9 | J35: 9 | K35: 8 | L35: 8 | M35: =SUM(I35:L35) -> 34 | N35: =M35+55 -> 89
... A42: 2022210405 | B42: 张金龙 | C42: 8 | D42: 8 | E42: 10 | F42: 9 | G42: 9 | H42: 8 | I42: 9 | J42: 9 | K42: 8 | L42: 8 | M42: =SUM(I42:L42) -> 34 | N42: =M42+55 -> 89
A43: 2022210407 | B43: 张克 | C43: 0 | D43: 0 | E43: 0 | F43: 0 | G43: 0 | H43: 0 | I43: 0 | J43: 0 | K43: 0 | L43: 0 | M43: 0 | N43: 0
A44: 2022210411 | B44: 张文抱 | C44: 8 | D44: 0 | E44: 9 | F44: 9 | G44: 0 | H44: 8 | I44: 0 | J44: 9 | K44: 0 | L44: 0 | M44: =SUM(I44:L44) -> 9 | N44: =M44+55 -> 64
A45: 2022210414 | B45: 张玉妍 | C45: 8 | D45: 8 | E45: 9 | F45: 9 | G45: 0 | H45: 8 | I45: 0 | J45: 9 | K45: 0 | L45: 8 | M45: =SUM(I45:L45) -> 17 | N45: =M45+55 -> 72
A46: 2022210416 | B46: 赵杰 | C46: 0 | D46: 8 | E46: 10 | F46: 9 | G46: 0 | H46: 8 | I46: 0 | J46: 9 | K46: 0 | L46: 0 | M46: =SUM(I46:L46) -> 9 | N46: =M46+55 -> 64
...

Sheet 课外学习
A1: 《移动应用开发》课外学习
A2: 学号 | B2: 姓名 | C2: 课程考核大作业1——项目启动 | D2: 课程考核大作业2——核心开发 | E2: 课程考核大作业3——系统整合 | F2: 课程考核大作业4——测试交付 | G2: 考核报告1——答辩报告 | H2: 考核报告2——个人报告 | I2: 考核报告3——小组报告 | J2: 考核报告4——项目报告 | K2: 课程考试大作业 | L2: 平均分
A3: 2020211034 | B3: 张梦杰 | C3: 80 | D3: 60 | E3: 90 | F3: 90 | G3: 80 | H3: 100 | I3: 80 | J3: 80 | K3: 0 | L3: =AVERAGE(C3:K3) -> 73.333333
A4: 2020213700 | B4: 童其凡 | C4: 80 | D4: 70 | E4: 70 | F4: 90 | G4: 80 | H4: 70 | I4: 70 | J4: 80 | K4: 0 | L4: =AVERAGE(C4:K4) -> 67.777778
A5: 2022210331 | B5: 曹安晨 | C5: 80 | D5: 70 | E5: 70 | F5: 90 | G5: 100 | H5: 80 | I5: 80 | J5: 80 | K5: 80 | L5: =AVERAGE(C5:K5) -> 81.111111
A6: 2022210332 | B6: 陈晨 | C6: 80 | D6: 100 | E6: 80 | F6: 90 | G6: 100 | H6: 90 | I6: 90 | J6: 90 | K6: 80 | L6: =AVERAGE(C6:K6) -> 88.888889
A7: 2022210333 | B7: 陈创东 | C7: 80 | D7: 100 | E7: 80 | F7: 90 | G7: 100 | H7: 100 | I7: 90 | J7: 90 | K7: 80 | L7: =AVERAGE(C7:K7) -> 90
A8: 2022210334 | B8: 程纪阳 | C8: 80 | D8: 80 | E8: 70 | F8: 90 | G8: 100 | H8: 90 | I8: 80 | J8: 80 | K8: 80 | L8: =AVERAGE(C8:K8) -> 83.333333
A9: 2022210335 | B9: 程梦圆 | C9: 70 | D9: 50 | E9: 60 | F9: 90 | G9: 90 | H9: 90 | I9: 80 | J9: 90 | K9: 80 | L9: =AVERAGE(C9:K9) -> 77.777778
A10: 2022210337 | B10: 邓慧茹 | C10: 80 | D10: 60 | E10: 60 | F10: 90 | G10: 100 | H10: 90 | I10: 80 | J10: 90 | K10: 80 | L10: =AVERAGE(C10:K10) -> 81.111111
A11: 2022210338 | B11: 丁玉耀 | C11: 0 | D11: 0 | E11: 0 | F11: 0 | G11: 0 | H11: 0 | I11: 0 | J11: 0 | K11: 0 | L11: 0
A12: 2022210339 | B12: 范鑫蕊 | C12: 80 | D12: 70 | E12: 60 | F12: 90 | G12: 100 | H12: 70 | I12: 80 | J12: 90 | K12: 70 | L12: =AVERAGE(C12:K12) -> 78.888889
A13: 2022210342 | B13: 高恩鹏 | C13: 60 | D13: 50 | E13: 70 | F13: 90 | G13: 100 | H13: 100 | I13: 80 | J13: 80 | K13: 80 | L13: =AVERAGE(C13:K13) -> 78.888889
A14: 2022210343 | B14: 关雪艳 | C14: 80 | D14: 70 | E14: 60 | F14: 100 | G14: 100 | H14: 100 | I14: 90 | J14: 90 | K14: 80 | L14: =AVERAGE(C14:K14) -> 85.555556
A15: 2022210344 | B15: 郭新杰 | C15: 80 | D15: 60 | E15: 60 | F15: 90 | G15: 100 | H15: 90 | I15: 80 | J15: 90 | K15: 70 | L15: =AVERAGE(C15:K15) -> 80
A16: 2022210346 | B16: 洪晓瑞 | C16: 60 | D16: 60 | E16: 70 | F16: 90 | G16: 100 | H16: 100 | I16: 90 | J16: 80 | K16: 80 | L16: =AVERAGE(C16:K16) -> 81.111111
A17: 2022210347 | B17: 胡步兴 | C17: 80 | D17: 70 | E17: 60 | F17: 90 | G17: 100 | H17: 100 | I17: 90 | J17: 90 | K17: 80 | L17: =AVERAGE(C17:K17) -> 84.444444
A18: 2022210348 | B18: 胡昊泱 | C18: 80 | D18: 100 | E18: 80 | F18: 90 | G18: 80 | H18: 100 | I18: 80 | J18: 90 | K18: 80 | L18: =AVERAGE(C18:K18) -> 86.666667
A19: 2022210351 | B19: 季玮 | C19: 70 | D19: 100 | E19: 80 | F19: 90 | G19: 100 | H19: 90 | I19: 70 | J19: 90 | K19: 80 | L19: =AVERAGE(C19:K19) -> 85.555556
A20: 2022210359 | B20: 李宝航 | C20: 0 | D20: 70 | E20: 90 | F20: 90 | G20: 80 | H20: 80 | I20: 80 | J20: 80 | K20: 0 | L20: =AVERAGE(C20:K20) -> 63.333333
A21: 2022210360 | B21: 李浩 | C21: 50 | D21: 100 | E21: 50 | F21: 90 | G21: 90 | H21: 80 | I21: 70 | J21: 80 | K21: 70 | L21: =AVERAGE(C21:K21) -> 75.555556
A22: 2022210361 | B22: 李今朝 | C22: 50 | D22: 60 | E22: 90 | F22: 90 | G22: 100 | H22: 70 | I22: 70 | J22: 90 | K22: 70 | L22: =AVERAGE(C22:K22) -> 76.666667
A23: 2022210362 | B23: 李良辰 | C23: 80 | D23: 80 | E23: 70 | F23: 90 | G23: 80 | H23: 90 | I23: 90 | J23: 80 | K23: 70 | L23: =AVERAGE(C23:K23) -> 81.111111
... A42: 2022210405 | B42: 张金龙 | C42: 70 | D42: 80 | E42: 70 | F42: 90 | G42: 100 | H42: 90 | I42: 80 | J42: 80 | K42: 80 | L42: =AVERAGE(C42:K42) -> 82.222222
A43: 2022210407 | B43: 张克 | C43: 0 | D43: 0 | E43: 0 | F43: 0 | G43: 0 | H43: 0 | I43: 0 | J43: 0 | K43: 0 | L43: 0
A44: 2022210411 | B44: 张文抱 | C44: 80 | D44: 80 | E44: 70 | F44: 90 | G44: 100 | H44: 100 | I44: 90 | J44: 80 | K44: 70 | L44: =AVERAGE(C44:K44) -> 84.444444
A45: 2022210414 | B45: 张玉妍 | C45: 80 | D45: 70 | E45: 70 | F45: 90 | G45: 100 | H45: 70 | I45: 80 | J45: 70 | K45: 70 | L45: =AVERAGE(C45:K45) -> 77.777778
A46: 2022210416 | B46: 赵杰 | C46: 80 | D46: 70 | E46: 90 | F46: 90 | G46: 90 | H46: 80 | I46: 70 | J46: 80 | K46: 70 | L46: =AVERAGE(C46:K46) -> 80
A47: 2022210417 | B47: 郑存耀 | C47: 80 | D47: 70 | E47: 90 | F47: 90 | G47: 90 | H47: 80 | I47: 90 | J47: 60 | K47: 80 | L47: =AVERAGE(C47:K47) -> 81.111111
A48: 2022210422 | B48: 周宇 | C48: 80 | D48: 60 | E48: 70 | F48: 90 | G48: 90 | H48: 90 | I48: 80 | J48: 80 | K48: 0 | L48: =AVERAGE(C48:K48) -> 71.111111
A49: 2022210423 | B49: 朱传双 | C49: 80 | D49: 70 | E49: 70 | F49: 90 | G49: 100 | H49: 90 | I49: 80 | J49: 80 | K49: 70 | L49: =AVERAGE(C49:K49) -> 81.111111
A50: 2022210428 | B50: 朱世俊 | C50: 80 | D50: 0 | E50: 60 | F50: 0 | G50: 100 | H50: 80 | I50: 70 | J50: 80 | K50: 80 | L50: =AVERAGE(C50:K50) -> 61.111111
A51: 2022210429 | B51: 祝文耿 | C51: 70 | D51: 70 | E51: 60 | F51: 90 | G51: 80 | H51: 80 | I51: 80 | J51: 90 | K51: 70 | L51: =AVERAGE(C51:K51) -> 76.666667
A52: 2022210430 | B52: 宗梦晴 | C52: 70 | D52: 80 | E52: 70 | F52: 90 | G52: 90 | H52: 80 | I52: 80 | J52: 80 | K52: 80 | L52: =AVERAGE(C52:K52) -> 80

Sheet 期间测验
A2: 《移动应用开发》期间测验
A3: 学号 | B3: 姓名 | C3: 作业1概述 | D3: 作业2原生Android | E3: 作业3原生iOS | F3: 作业4原生应用开发 | G3: 作业5Flutter混合应用 | H3: 作业6Cordova&UniApp混合应用 | I3: 作业7 MAUI&&WXMiniApp | J3: 作业8小程序2 | K3: 作业9华为多端应用开发1 | L3: 作业10华为多端应用开发2 | M3: 平均分
A4: 2020211034 | B4: 张梦杰 | C4: 80 | D4: 80 | E4: 100 | F4: 80 | G4: 80 | H4: 80 | I4: 0 | J4: 100 | K4: 100 | L4: 0 | M4: =AVERAGE(C4:L4) -> 70
A5: 2020213700 | B5: 童其凡 | C5: 100 | D5: 100 | E5: 100 | F5: 90 | G5: 100 | H5: 100 | I5: 100 | J5: 100 | K5: 100 | L5: 100 | M5: =AVERAGE(C5:L5) -> 99
A6: 2022210331 | B6: 曹安晨 | C6: 100 | D6: 100 | E6: 100 | F6: 80 | G6: 100 | H6: 100 | I6: 80 | J6: 100 | K6: 100 | L6: 100 | M6: =AVERAGE(C6:L6) -> 96
A7: 2022210332 | B7: 陈晨 | C7: 100 | D7: 100 | E7: 100 | F7: 100 | G7: 100 | H7: 100 | I7: 100 | J7: 100 | K7: 100 | L7: 100 | M7: =AVERAGE(C7:L7) -> 100
A8: 2022210333 | B8: 陈创东 | C8: 80 | D8: 80 | E8: 100 | F8: 90 | G8: 100 | H8: 100 | I8: 100 | J8: 0 | K8: 100 | L8: 100 | M8: =AVERAGE(C8:L8) -> 85
A9: 2022210334 | B9: 程纪阳 | C9: 100 | D9: 100 | E9: 100 | F9: 90 | G9: 100 | H9: 100 | I9: 100 | J9: 100 | K9: 100 | L9: 100 | M9: =AVERAGE(C9:L9) -> 99
A10: 2022210335 | B10: 程梦圆 | C10: 100 | D10: 80 | E10: 100 | F10: 80 | G10: 100 | H10: 100 | I10: 0 | J10: 100 | K10: 100 | L10: 100 | M10: =AVERAGE(C10:L10) -> 86
A11: 2022210337 | B11: 邓慧茹 | C11: 100 | D11: 80 | E11: 100 | F11: 80 | G11: 100 | H11: 100 | I11: 90 | J11: 100 | K11: 100 | L11: 90 | M11: =AVERAGE(C11:L11) -> 94
A12: 2022210338 | B12: 丁玉耀 | C12: 80 | D12: 80 | E12: 0 | F12: 0 | G12: 0 | H12: 0 | I12: 0 | J12: 0 | K12: 0 | L12: 0 | M12: =AVERAGE(C12:L12) -> 16
A13: 2022210339 | B13: 范鑫蕊 | C13: 100 | D13: 100 | E13: 100 | F13: 80 | G13: 100 | H13: 100 | I13: 90 | J13: 100 | K13: 100 | L13: 100 | M13: =AVERAGE(C13:L13) -> 97
A14: 2022210342 | B14: 高恩鹏 | C14: 100 | D14: 80 | E14: 100 | F14: 100 | G14: 100 | H14: 100 | I14: 80 | J14: 80 | K14: 100 | L14: 100 | M14: =AVERAGE(C14:L14) -> 94
A15: 2022210343 | B15: 关雪艳 | C15: 100 | D15: 100 | E15: 100 | F15: 100 | G15: 100 | H15: 100 | I15: 100 | J15: 100 | K15: 100 | L15: 100 | M15: =AVERAGE(C15:L15) -> 100
... A53: 2022210430 | B53: 宗梦晴 | C53: 100 | D53: 100 | E53: 80 | F53: 90 | G53: 100 | H53: 100 | I53: 90 | J53: 100 | K53: 0 | L53: 100 | M53: =AVERAGE(C53:L53) -> 86

Sheet 实验成绩
A1: 《移动应用开发》实验成绩
A2: 学号 | B2: 姓名 | C2: 实验一 | D2: 实验二 | E2: 实验三 | F2: 实验四 | G2: 实验五 | H2: 实验六 | I2: 实验七 | J2: 平均分
A3: =[1]作业统计!B5 -> 2020211034 | B3: =[1]作业统计!A5 -> 张梦杰 | C3: =[1]作业统计!F5 -> 80 | D3: =[1]作业统计!O5 -> 80 | E3: =[1]作业统计!X5 -> 80 | F3: =[1]作业统计!AG5 -> 100 | G3: =[1]作业统计!AM5 -> 70 | H3: =[1]作业统计!AP5 -> 70 | I3: =[1]作业统计!BB5 -> 70 | J3: =AVERAGE(C3:I3) -> 78.571429
A4: =[1]作业统计!B6 -> 2020213700 | B4: =[1]作业统计!A6 -> 童其凡 | C4: =[1]作业统计!F6 -> 90 | D4: =[1]作业统计!O6 -> 90 | E4: =[1]作业统计!X6 -> 80 | F4: =[1]作业统计!AG6 -> 100 | G4: =[1]作业统计!AM6 -> 60 | H4: =[1]作业统计!AP6 -> 90 | I4: =[1]作业统计!BB6 -> 70 | J4: =AVERAGE(C4:I4) -> 82.857143
A5: =[1]作业统计!B7 -> 2022210331 | B5: =[1]作业统计!A7 -> 曹安晨 | C5: =[1]作业统计!F7 -> 100 | D5: =[1]作业统计!O7 -> 90 | E5: =[1]作业统计!X7 -> 100 | F5: =[1]作业统计!AG7 -> 100 | G5: =[1]作业统计!AM7 -> 70 | H5: =[1]作业统计!AP7 -> 80 | I5: =[1]作业统计!BB7 -> 70 | J5: =AVERAGE(C5:I5) -> 87.142857
A6: =[1]作业统计!B8 -> 2022210332 | B6: =[1]作业统计!A8 -> 陈晨 | C6: =[1]作业统计!F8 -> 100 | D6: =[1]作业统计!O8 -> 90 | E6: =[1]作业统计!X8 -> 70 | F6: =[1]作业统计!AG8 -> 100 | G6: =[1]作业统计!AM8 -> 80 | H6: =[1]作业统计!AP8 -> 90 | I6: =[1]作业统计!BB8 -> 70 | J6: =AVERAGE(C6:I6) -> 85.714286
A7: =[1]作业统计!B9 -> 2022210333 | B7: =[1]作业统计!A9 -> 陈创东 | C7: =[1]作业统计!F9 -> 100 | D7: =[1]作业统计!O9 -> 60 | E7: =[1]作业统计!X9 -> 70 | F7: =[1]作业统计!AG9 -> 80 | G7: =[1]作业统计!AM9 -> 95 | H7: =[1]作业统计!AP9 -> 90 | I7: =[1]作业统计!BB9 -> 60 | J7: =AVERAGE(C7:I7) -> 79.285714
A8: =[1]作业统计!B10 -> 2022210334 | B8: =[1]作业统计!A10 -> 程纪阳 | C8: =[1]作业统计!F10 -> 80 | D8: =[1]作业统计!O10 -> 100 | E8: =[1]作业统计!X10 -> 100 | F8: =[1]作业统计!AG10 -> 100 | G8: =[1]作业统计!AM10 -> 80 | H8: =[1]作业统计!AP10 -> 80 | I8: =[1]作业统计!BB10 -> 80 | J8: =AVERAGE(C8:I8) -> 88.571429
A9: =[1]作业统计!B11 -> 2022210335 | B9: =[1]作业统计!A11 -> 程梦圆 | C9: =[1]作业统计!F11 -> 100 | D9: =[1]作业统计!O11 -> 90 | E9: =[1]作业统计!X11 -> 80 | F9: =[1]作业统计!AG11 -> 100 | G9: =[1]作业统计!AM11 -> 80 | H9: =[1]作业统计!AP11 -> 70 | I9: =[1]作业统计!BB11 -> 70 | J9: =AVERAGE(C9:I9) -> 84.285714
A10: =[1]作业统计!B12 -> 2022210337 | B10: =[1]作业统计!A12 -> 邓慧茹 | C10: =[1]作业统计!F12 -> 100 | D10: =[1]作业统计!O12 -> 80 | E10: =[1]作业统计!X12 -> 95 | F10: =[1]作业统计!AG12 -> 90 | G10: =[1]作业统计!AM12 -> 80 | H10: =[1]作业统计!AP12 -> 60 | I10: =[1]作业统计!BB12 -> 70 | J10: =AVERAGE(C10:I10) -> 82.142857
A11: =[1]作业统计!B13 -> 2022210338 | B11: =[1]作业统计!A13 -> 丁玉耀 | C11: 0 | D11: 0 | E11: 0 | F11: 0 | G11: 0 | H11: 0 | I11: 0 | J11: 0
A12: =[1]作业统计!B14 -> 2022210339 | B12: =[1]作业统计!A14 -> 范鑫蕊 | C12: =[1]作业统计!F14 -> 100 | D12: =[1]作业统计!O14 -> 80 | E12: =[1]作业统计!X14 -> 90 | F12: =[1]作业统计!AG14 -> 80 | G12: =[1]作业统计!AM14 -> 70 | H12: =[1]作业统计!AP14 -> 80 | I12: =[1]作业统计!BB14 -> 70 | J12: =AVERAGE(C12:I12) -> 81.428571
A13: =[1]作业统计!B15 -> 2022210342 | B13: =[1]作业统计!A15 -> 高恩鹏 | C13: =[1]作业统计!F15 -> 100 | D13: =[1]作业统计!O15 -> 100 | E13: =[1]作业统计!X15 -> 80 | F13: =[1]作业统计!AG15 -> 100 | G13: =[1]作业统计!AM15 -> 80 | H13: =[1]作业统计!AP15 -> 80 | I13: =[1]作业统计!BB15 -> 95 | J13: =AVERAGE(C13:I13) -> 90.714286
A14: =[1]作业统计!B16 -> 2022210343 | B14: =[1]作业统计!A16 -> 关雪艳 | C14: =[1]作业统计!F16 -> 100 | D14: =[1]作业统计!O16 -> 80 | E14: =[1]作业统计!X16 -> 90 | F14: =[1]作业统计!AG16 -> 95 | G14: =[1]作业统计!AM16 -> 80 | H14: =[1]作业统计!AP16 -> 80 | I14: =[1]作业统计!BB16 -> 70 | J14: =AVERAGE(C14:I14) -> 85
A15: =[1]作业统计!B17 -> 2022210344 | B15: =[1]作业统计!A17 -> 郭新杰 | C15: =[1]作业统计!F17 -> 100 | D15: =[1]作业统计!O17 -> 90 | E15: =[1]作业统计!X17 -> 70 | F15: =[1]作业统计!AG17 -> 100 | G15: =[1]作业统计!AM17 -> 80 | H15: =[1]作业统计!AP17 -> 70 | I15: =[1]作业统计!BB17 -> 70 | J15: =AVERAGE(C15:I15) -> 82.857143
A16: =[1]作业统计!B18 -> 2022210346 | B16: =[1]作业统计!A18 -> 洪晓瑞 | C16: =[1]作业统计!F18 -> 100 | D16: =[1]作业统计!O18 -> 100 | E16: =[1]作业统计!X18 -> 80 | F16: =[1]作业统计!AG18 -> 100 | G16: =[1]作业统计!AM18 -> 70 | H16: =[1]作业统计!AP18 -> 80 | I16: =[1]作业统计!BB18 -> 95 | J16: =AVERAGE(C16:I16) -> 89.285714
A17: =[1]作业统计!B19 -> 2022210347 | B17: =[1]作业统计!A19 -> 胡步兴 | C17: =[1]作业统计!F19 -> 100 | D17: =[1]作业统计!O19 -> 90 | E17: =[1]作业统计!X19 -> 90 | F17: =[1]作业统计!AG19 -> 95 | G17: =[1]作业统计!AM19 -> 90 | H17: =[1]作业统计!AP19 -> 80 | I17: =[1]作业统计!BB19 -> 70 | J17: =AVERAGE(C17:I17) -> 87.857143
A18: =[1]作业统计!B20 -> 2022210348 | B18: =[1]作业统计!A20 -> 胡昊泱 | C18: =[1]作业统计!F20 -> 100 | D18: =[1]作业统计!O20 -> 80 | E18: =[1]作业统计!X20 -> 70 | F18: =[1]作业统计!AG20 -> 100 | G18: =[1]作业统计!AM20 -> 80 | H18: =[1]作业统计!AP20 -> 70 | I18: =[1]作业统计!BB20 -> 70 | J18: =AVERAGE(C18:I18) -> 81.428571
A19: =[1]作业统计!B21 -> 2022210351 | B19: =[1]作业统计!A21 -> 季玮 | C19: =[1]作业统计!F21 -> 100 | D19: =[1]作业统计!O21 -> 80 | E19: =[1]作业统计!X21 -> 100 | F19: =[1]作业统计!AG21 -> 100 | G19: =[1]作业统计!AM21 -> 90 | H19: =[1]作业统计!AP21 -> 80 | I19: =[1]作业统计!BB21 -> 70 | J19: =AVERAGE(C19:I19) -> 88.571429
A20: =[1]作业统计!B22 -> 2022210359 | B20: =[1]作业统计!A22 -> 李宝航 | C20: 0 | D20: 0 | E20: 0 | F20: 0 | G20: 0 | H20: 0 | I20: 0 | J20: 0
A21: =[1]作业统计!B23 -> 2022210360 | B21: =[1]作业统计!A23 -> 李浩 | C21: =[1]作业统计!F23 -> 100 | D21: =[1]作业统计!O23 -> 95 | E21: =[1]作业统计!X23 -> 80 | F21: =[1]作业统计!AG23 -> 100 | G21: =[1]作业统计!AM23 -> 90 | H21: =[1]作业统计!AP23 -> 80 | I21: =[1]作业统计!BB23 -> 70 | J21: =AVERAGE(C21:I21) -> 87.857143
A22: =[1]作业统计!B24 -> 2022210361 | B22: =[1]作业统计!A24 -> 李今朝 | C22: =[1]作业统计!F24 -> 100 | D22: =[1]作业统计!O24 -> 90 | E22: =[1]作业统计!X24 -> 80 | F22: =[1]作业统计!AG24 -> 100 | G22: =[1]作业统计!AM24 -> 70 | H22: 0 | I22: =[1]作业统计!BB24 -> 60 | J22: =AVERAGE(C22:I22) -> 71.428571
A23: =[1]作业统计!B25 -> 2022210362 | B23: =[1]作业统计!A25 -> 李良辰 | C23: =[1]作业统计!F25 -> 100 | D23: =[1]作业统计!O25 -> 80 | E23: =[1]作业统计!X25 -> 70 | F23: =[1]作业统计!AG25 -> 90 | G23: =[1]作业统计!AM25 -> 50 | H23: =[1]作业统计!AP25 -> 80 | I23: =[1]作业统计!BB25 -> 50 | J23: =AVERAGE(C23:I23) -> 74.285714
A24: =[1]作业统计!B26 -> 2022210367 | B24: =[1]作业统计!A26 -> 梁平 | C24: =[1]作业统计!F26 -> 80 | D24: =[1]作业统计!O26 -> 90 | E24: =[1]作业统计!X26 -> 80 | F24: =[1]作业统计!AG26 -> 100 | G24: =[1]作业统计!AM26 -> 60 | H24: =[1]作业统计!AP26 -> 90 | I24: =[1]作业统计!BB26 -> 60 | J24: =AVERAGE(C24:I24) -> 80
A25: =[1]作业统计!B27 -> 2022210371 | B25: =[1]作业统计!A27 -> 陆征宇 | C25: =[1]作业统计!F27 -> 80 | D25: =[1]作业统计!O27 -> 90 | E25: =[1]作业统计!X27 -> 100 | F25: =[1]作业统计!AG27 -> 90 | G25: =[1]作业统计!AM27 -> 70 | H25: =[1]作业统计!AP27 -> 70 | I25: =[1]作业统计!BB27 -> 70 | J25: =AVERAGE(C25:I25) -> 81.428571
A26: =[1]作业统计!B28 -> 2022210374 | B26: =[1]作业统计!A28 -> 苗佳宇 | C26: =[1]作业统计!F28 -> 100 | D26: =[1]作业统计!O28 -> 100 | E26: =[1]作业统计!X28 -> 95 | F26: =[1]作业统计!AG28 -> 100 | G26: =[1]作业统计!AM28 -> 70 | H26: =[1]作业统计!AP28 -> 80 | I26: =[1]作业统计!BB28 -> 80 | J26: =AVERAGE(C26:I26) -> 89.285714
A27: =[1]作业统计!B29 -> 2022210376 | B27: =[1]作业统计!A29 -> 庞雨俊 | C27: =[1]作业统计!F29 -> 100 | D27: =[1]作业统计!O29 -> 80 | E27: =[1]作业统计!X29 -> 70 | F27: =[1]作业统计!AG29 -> 100 | G27: =[1]作业统计!AM29 -> 70 | H27: =[1]作业统计!AP29 -> 70 | I27: =[1]作业统计!BB29 -> 95 | J27: =AVERAGE(C27:I27) -> 83.571429
A28: =[1]作业统计!B30 -> 2022210378 | B28: =[1]作业统计!A30 -> 戚锐 | C28: =[1]作业统计!F30 -> 100 | D28: =[1]作业统计!O30 -> 100 | E28: =[1]作业统计!X30 -> 100 | F28: =[1]作业统计!AG30 -> 100 | G28: =[1]作业统计!AM30 -> 95 | H28: =[1]作业统计!AP30 -> 80 | I28: =[1]作业统计!BB30 -> 80 | J28: =AVERAGE(C28:I28) -> 93.571429
A29: =[1]作业统计!B31 -> 2022210380 | B29: =[1]作业统计!A31 -> 任奕凯 | C29: =[1]作业统计!F31 -> 100 | D29: =[1]作业统计!O31 -> 80 | E29: =[1]作业统计!X31 -> 70 | F29: =[1]作业统计!AG31 -> 100 | G29: =[1]作业统计!AM31 -> 80 | H29: =[1]作业统计!AP31 -> 80 | I29: =[1]作业统计!BB31 -> 70 | J29: =AVERAGE(C29:I29) -> 82.857143
A30: =[1]作业统计!B32 -> 2022210381 | B30: =[1]作业统计!A32 -> 阮珧 | C30: =[1]作业统计!F32 -> 80 | D30: =[1]作业统计!O32 -> 80 | E30: =[1]作业统计!X32 -> 80 | F30: =[1]作业统计!AG32 -> 80 | G30: =[1]作业统计!AM32 -> 60 | H30: =[1]作业统计!AP32 -> 80 | I30: =[1]作业统计!BB32 -> 60 | J30: =AVERAGE(C30:I30) -> 74.285714
A31: =[1]作业统计!B33 -> 2022210384 | B31: =[1]作业统计!A33 -> 孙嘉婧 | C31: =[1]作业统计!F33 -> 80 | D31: =[1]作业统计!O33 -> 70 | E31: =[1]作业统计!X33 -> 80 | F31: =[1]作业统计!AG33 -> 100 | G31: =[1]作业统计!AM33 -> 80 | H31: =[1]作业统计!AP33 -> 80 | I31: =[1]作业统计!BB33 -> 70 | J31: =AVERAGE(C31:I31) -> 80
A32: =[1]作业统计!B34 -> 2022210385 | B32: =[1]作业统计!A34 -> 孙锦年 | C32: =[1]作业统计!F34 -> 100 | D32: =[1]作业统计!O34 -> 80 | E32: =[1]作业统计!X34 -> 80 | F32: =[1]作业统计!AG34 -> 80 | G32: =[1]作业统计!AM34 -> 80 | H32: =[1]作业统计!AP34 -> 80 | I32: =[1]作业统计!BB34 -> 60 | J32: =AVERAGE(C32:I32) -> 80
A33: =[1]作业统计!B35 -> 2022210387 | B33: =[1]作业统计!A35 -> 唐蕊 | C33: =[1]作业统计!F35 -> 90 | D33: =[1]作业统计!O35 -> 80 | E33: =[1]作业统计!X35 -> 80 | F33: =[1]作业统计!AG35 -> 100 | G33: =[1]作业统计!AM35 -> 90 | H33: =[1]作业统计!AP35 -> 80 | I33: =[1]作业统计!BB35 -> 70 | J33: =AVERAGE(C33:I33) -> 84.285714
A34: =[1]作业统计!B36 -> 2022210389 | B34: =[1]作业统计!A36 -> 汪海洋 | C34: =[1]作业统计!F36 -> 100 | D34: =[1]作业统计!O36 -> 60 | E34: =[1]作业统计!X36 -> 90 | F34: =[1]作业统计!AG36 -> 90 | G34: =[1]作业统计!AM36 -> 80 | H34: =[1]作业统计!AP36 -> 80 | I34: =[1]作业统计!BB36 -> 70 | J34: =AVERAGE(C34:I34) -> 81.428571
... A42: =[1]作业统计!B44 -> 2022210405 | B42: =[1]作业统计!A44 -> 张金龙 | C42: =[1]作业统计!F44 -> 100 | D42: =[1]作业统计!O44 -> 90 | E42: =[1]作业统计!X44 -> 80 | F42: =[1]作业统计!AG44 -> 90 | G42: =[1]作业统计!AM44 -> 80 | H42: =[1]作业统计!AP44 -> 80 | I42: =[1]作业统计!BB44 -> 70 | J42: =AVERAGE(C42:I42) -> 84.285714
A43: =[1]作业统计!B45 -> 2022210407 | B43: =[1]作业统计!A45 -> 张克 | C43: 0 | D43: 0 | E43: 0 | F43: 0 | G43: 0 | H43: 0 | I43: 0 | J43: 0
A44: =[1]作业统计!B46 -> 2022210411 | B44: =[1]作业统计!A46 -> 张文抱 | C44: =[1]作业统计!F46 -> 100 | D44: =[1]作业统计!O46 -> 80 | E44: =[1]作业统计!X46 -> 90 | F44: =[1]作业统计!AG46 -> 90 | G44: =[1]作业统计!AM46 -> 90 | H44: =[1]作业统计!AP46 -> 80 | I44: =[1]作业统计!BB46 -> 80 | J44: =AVERAGE(C44:I44) -> 87.142857
A45: =[1]作业统计!B47 -> 2022210414 | B45: =[1]作业统计!A47 -> 张玉妍 | C45: =[1]作业统计!F47 -> 100 | D45: =[1]作业统计!O47 -> 95 | E45: =[1]作业统计!X47 -> 80 | F45: =[1]作业统计!AG47 -> 100 | G45: =[1]作业统计!AM47 -> 70 | H45: =[1]作业统计!AP47 -> 80 | I45: =[1]作业统计!BB47 -> 70 | J45: =AVERAGE(C45:I45) -> 85
A46: =[1]作业统计!B48 -> 2022210416 | B46: =[1]作业统计!A48 -> 赵杰 | C46: =[1]作业统计!F48 -> 80 | D46: =[1]作业统计!O48 -> 90 | E46: =[1]作业统计!X48 -> 70 | F46: =[1]作业统计!AG48 -> 90 | G46: =[1]作业统计!AM48 -> 70 | H46: =[1]作业统计!AP48 -> 70 | I46: =[1]作业统计!BB48 -> 60 | J46: =AVERAGE(C46:I46) -> 75.714286
A47: =[1]作业统计!B49 -> 2022210417 | B47: =[1]作业统计!A49 -> 郑存耀 | C47: =[1]作业统计!F49 -> 100 | D47: =[1]作业统计!O49 -> 60 | E47: =[1]作业统计!X49 -> 100 | F47: =[1]作业统计!AG49 -> 100 | G47: =[1]作业统计!AM49 -> 80 | H47: =[1]作业统计!AP49 -> 70 | I47: 0 | J47: =AVERAGE(C47:I47) -> 72.857143
...

Sheet 大作业
A1: 《移动应用开发》课程考核大作业 2025.11.24
A2: 学号 | B2: 姓名 | C2: 项目(30%) | D2: 小组(20%) | E2: 个人(20%) | F2: 答辩(30%) | G2: 总分(2位) | H2: 总分
A3: 2020211034 | B3: 张梦杰 | C3: 76 | D3: 71 | E3: 72 | F3: 68 | G3: =C3*0.3+D3*0.2+E3*0.2+F3*0.3 -> 71.8 | H3: 71.8
A4: 2020213700 | B4: 童其凡 | C4: 76 | D4: 70 | E4: 50 | F4: 80 | G4: =C4*0.3+D4*0.2+E4*0.2+F4*0.3 -> 70.8 | H4: 70.8
A5: 2022210331 | B5: 曹安晨 | C5: 62 | D5: 50 | E5: 50 | F5: 60 | G5: =C5*0.3+D5*0.2+E5*0.2+F5*0.3 -> 56.6 | H5: 56.6
A6: 2022210332 | B6: 陈晨 | C6: 92 | D6: 91 | E6: 92 | F6: 87 | G6: =C6*0.3+D6*0.2+E6*0.2+F6*0.3 -> 90.3 | H6: 90.3
A7: 2022210333 | B7: 陈创东 | C7: 92 | D7: 91 | E7: 92 | F7: 93 | G7: =C7*0.3+D7*0.2+E7*0.2+F7*0.3 -> 92.1 | H7: 92.1
A8: 2022210334 | B8: 程纪阳 | C8: 78 | D8: 78 | E8: 86 | F8: 87 | G8: =C8*0.3+D8*0.2+E8*0.2+F8*0.3 -> 82.3 | H8: 82.3
A9: 2022210335 | B9: 程梦圆 | C9: 50 | D9: 50 | E9: 70 | F9: 62.7 | G9: =C9*0.3+D9*0.2+E9*0.2+F9*0.3 -> 57.81 | H9: 57.81
A10: 2022210337 | B10: 邓慧茹 | C10: 88 | D10: 80 | E10: 90 | F10: 74 | G10: =C10*0.3+D10*0.2+E10*0.2+F10*0.3 -> 82.6 | H10: 82.6
A11: 2022210338 | B11: 丁玉耀 | C11: 0 | D11: 0 | E11: 0 | F11: 0 | G11: 0 | H11: 0
A12: 2022210339 | B12: 范鑫蕊 | C12: 80 | D12: 70 | E12: 72 | F12: 78 | G12: =C12*0.3+D12*0.2+E12*0.2+F12*0.3 -> 75.8 | H12: 75.8
A13: 2022210342 | B13: 高恩鹏 | C13: 94 | D13: 92 | E13: 94 | F13: 84.7 | G13: =C13*0.3+D13*0.2+E13*0.2+F13*0.3 -> 90.81 | H13: 90.81
A14: 2022210343 | B14: 关雪艳 | C14: 90 | D14: 90 | E14: 94 | F14: 90 | G14: =C14*0.3+D14*0.2+E14*0.2+F14*0.3 -> 90.8 | H14: 90.8
A15: 2022210344 | B15: 郭新杰 | C15: 80 | D15: 70 | E15: 70 | F15: 83.3 | G15: =C15*0.3+D15*0.2+E15*0.2+F15*0.3 -> 76.99 | H15: 76.99
A16: 2022210346 | B16: 洪晓瑞 | C16: 90 | D16: 90 | E16: 90 | F16: 93 | G16: =C16*0.3+D16*0.2+E16*0.2+F16*0.3 -> 90.9 | H16: 90.9
A17: 2022210347 | B17: 胡步兴 | C17: 86 | D17: 84 | E17: 88 | F17: 80 | G17: =C17*0.3+D17*0.2+E17*0.2+F17*0.3 -> 84.2 | H17: 84.2
A18: 2022210348 | B18: 胡昊泱 | C18: 80 | D18: 76 | E18: 80 | F18: 82 | G18: =C18*0.3+D18*0.2+E18*0.2+F18*0.3 -> 79.8 | H18: 79.8
A19: 2022210351 | B19: 季玮 | C19: 78 | D19: 76 | E19: 80 | F19: 84 | G19: =C19*0.3+D19*0.2+E19*0.2+F19*0.3 -> 79.8 | H19: 79.8
A20: 2022210359 | B20: 李宝航 | C20: 80 | D20: 70 | E20: 80 | F20: 83.3 | G20: =C20*0.3+D20*0.2+E20*0.2+F20*0.3 -> 78.99 | H20: 78.99
A21: 2022210360 | B21: 李浩 | C21: 70 | D21: 70 | E21: 68 | F21: 74 | G21: =C21*0.3+D21*0.2+E21*0.2+F21*0.3 -> 70.8 | H21: 70.8
A22: 2022210361 | B22: 李今朝 | C22: 90 | D22: 88 | E22: 93 | F22: 90.7 | G22: =C22*0.3+D22*0.2+E22*0.2+F22*0.3 -> 90.41 | H22: 90.41
A23: 2022210362 | B23: 李良辰 | C23: 70 | D23: 70 | E23: 64 | F23: 60 | G23: =C23*0.3+D23*0.2+E23*0.2+F23*0.3 -> 65.8 | H23: 65.8
... A42: 2022210405 | B42: 张金龙 | C42: 78 | D42: 76 | E42: 80 | F42: 90 | G42: =C42*0.3+D42*0.2+E42*0.2+F42*0.3 -> 81.6 | H42: 81.6
A43: 2022210407 | B43: 张克 | C43: 0 | D43: 0 | E43: 0 | F43: 0 | G43: 0 | H43: 0
A44: 2022210411 | B44: 张文抱 | C44: 50 | D44: 50 | E44: 50 | F44: 60 | G44: =C44*0.3+D44*0.2+E44*0.2+F44*0.3 -> 53 | H44: 53
A45: 2022210414 | B45: 张玉妍 | C45: 86 | D45: 82 | E45: 80 | F45: 81 | G45: =C45*0.3+D45*0.2+E45*0.2+F45*0.3 -> 82.5 | H45: 82.5
A46: 2022210416 | B46: 赵杰 | C46: 64 | D46: 62 | E46: 68 | F46: 67.3 | G46: =C46*0.3+D46*0.2+E46*0.2+F46*0.3 -> 65.39 | H46: 65.39
A47: 2022210417 | B47: 郑存耀 | C47: 80 | D47: 78 | E47: 78 | F47: 70 | G47: =C47*0.3+D47*0.2+E47*0.2+F47*0.3 -> 76.2 | H47: 76.2
A48: 2022210422 | B48: 周宇 | C48: 80 | D48: 70 | E48: 76 | F48: 76.7 | G48: =C48*0.3+D48*0.2+E48*0.2+F48*0.3 -> 76.21 | H48: 76.21
A49: 2022210423 | B49: 朱传双 | C49: 60 | D49: 60 | E49: 50 | F49: 60 | G49: =C49*0.3+D49*0.2+E49*0.2+F49*0.3 -> 58 | H49: 58
A50: 2022210428 | B50: 朱世俊 | C50: 78 | D50: 76 | E50: 78 | F50: 77 | G50: =C50*0.3+D50*0.2+E50*0.2+F50*0.3 -> 77.3 | H50: 77.3
A51: 2022210429 | B51: 祝文耿 | C51: 76 | D51: 74 | E51: 60 | F51: 60 | G51: =C51*0.3+D51*0.2+E51*0.2+F51*0.3 -> 67.6 | H51: 67.6
A52: 2022210430 | B52: 宗梦晴 | C52: 92 | D52: 92 | E52: 94 | F52: 90 | G52: =C52*0.3+D52*0.2+E52*0.2+F52*0.3 -> 91.8 | H52: 91.8

Sheet 汇总成绩
A1: 《移动应用开发》成绩汇总表
A2: 学号 | B2: 姓名 | C2: 平时(20%) | G2: 实验（30%） | H2: 大作业（50%） | I2: 总成绩
C3: 课堂表现(20%) | D3: 课外学习(50%) | E3: 期间测验(30%) | F3: 平时小计
A4: 2020211034 | B4: 张梦杰 | C4: 64 | D4: 73.333333 | E4: 70 | F4: =C4*0.2+D4*0.5+E4*0.3 -> 70.466667 | G4: 78.571429 | H4: 71.8 | I4: =F4*0.2+H4*0.5+G4*0.3 -> 73.564762
A5: 2020213700 | B5: 童其凡 | C5: 81 | D5: 67.777778 | E5: 99 | F5: =C5*0.2+D5*0.5+E5*0.3 -> 79.788889 | G5: 82.857143 | H5: 70.8 | I5: =F5*0.2+H5*0.5+G5*0.3 -> 76.214921
A6: 2022210331 | B6: 曹安晨 | C6: 89 | D6: 81.111111 | E6: 96 | F6: =C6*0.2+D6*0.5+E6*0.3 -> 87.155556 | G6: 87.142857 | H6: 56.6 | I6: =F6*0.2+H6*0.5+G6*0.3 -> 71.873968
A7: 2022210332 | B7: 陈晨 | C7: 89 | D7: 88.888889 | E7: 100 | F7: =C7*0.2+D7*0.5+E7*0.3 -> 92.244444 | G7: 85.714286 | H7: 90.3 | I7: =F7*0.2+H7*0.5+G7*0.3 -> 89.313175
A8: 2022210333 | B8: 陈创东 | C8: 81 | D8: 90 | E8: 85 | F8: =C8*0.2+D8*0.5+E8*0.3 -> 86.7 | G8: 79.285714 | H8: 92.1 | I8: =F8*0.2+H8*0.5+G8*0.3 -> 87.175714
A9: 2022210334 | B9: 程纪阳 | C9: 89 | D9: 83.333333 | E9: 99 | F9: =C9*0.2+D9*0.5+E9*0.3 -> 89.166667 | G9: 88.571429 | H9: 82.3 | I9: =F9*0.2+H9*0.5+G9*0.3 -> 85.554762
A10: 2022210335 | B10: 程梦圆 | C10: 81 | D10: 77.777778 | E10: 86 | F10: =C10*0.2+D10*0.5+E10*0.3 -> 80.888889 | G10: 84.285714 | H10: 57.81 | I10: =F10*0.2+H10*0.5+G10*0.3 -> 70.368492
A11: 2022210337 | B11: 邓慧茹 | C11: 89 | D11: 81.111111 | E11: 94 | F11: =C11*0.2+D11*0.5+E11*0.3 -> 86.555556 | G11: 82.142857 | H11: 82.6 | I11: =F11*0.2+H11*0.5+G11*0.3 -> 83.253968
A12: 2022210338 | B12: 丁玉耀 | C12: 0 | D12: 0 | E12: 16 | F12: =C12*0.2+D12*0.5+E12*0.3 -> 4.8 | G12: 0 | H12: 旷缺 | I12: 1
A13: 2022210339 | B13: 范鑫蕊 | C13: 89 | D13: 78.888889 | E13: 97 | F13: =C13*0.2+D13*0.5+E13*0.3 -> 86.344444 | G13: 81.428571 | H13: 75.8 | I13: =F13*0.2+H13*0.5+G13*0.3 -> 79.59746
A14: 2022210342 | B14: 高恩鹏 | C14: 81 | D14: 78.888889 | E14: 94 | F14: =C14*0.2+D14*0.5+E14*0.3 -> 83.844444 | G14: 90.714286 | H14: 90.81 | I14: =F14*0.2+H14*0.5+G14*0.3 -> 89.388175
A15: 2022210343 | B15: 关雪艳 | C15: 89 | D15: 85.555556 | E15: 100 | F15: =C15*0.2+D15*0.5+E15*0.3 -> 90.577778 | G15: 85 | H15: 90.8 | I15: =F15*0.2+H15*0.5+G15*0.3 -> 89.015556
A16: 2022210344 | B16: 郭新杰 | C16: 89 | D16: 80 | E16: 91 | F16: =C16*0.2+D16*0.5+E16*0.3 -> 85.1 | G16: 82.857143 | H16: 76.99 | I16: =F16*0.2+H16*0.5+G16*0.3 -> 80.372143
A17: 2022210346 | B17: 洪晓瑞 | C17: 81 | D17: 81.111111 | E17: 92 | F17: =C17*0.2+D17*0.5+E17*0.3 -> 84.355556 | G17: 89.285714 | H17: 90.9 | I17: =F17*0.2+H17*0.5+G17*0.3 -> 89.106825
A18: 2022210347 | B18: 胡步兴 | C18: 81 | D18: 84.444444 | E18: 99 | F18: =C18*0.2+D18*0.5+E18*0.3 -> 88.122222 | G18: 87.857143 | H18: 84.2 | I18: =F18*0.2+H18*0.5+G18*0.3 -> 86.081587
A19: 2022210348 | B19: 胡昊泱 | C19: 81 | D19: 86.666667 | E19: 94 | F19: =C19*0.2+D19*0.5+E19*0.3 -> 87.733333 | G19: 81.428571 | H19: 79.8 | I19: =F19*0.2+H19*0.5+G19*0.3 -> 81.875238
A20: 2022210351 | B20: 季玮 | C20: 89 | D20: 85.555556 | E20: 95 | F20: =C20*0.2+D20*0.5+E20*0.3 -> 89.077778 | G20: 88.571429 | H20: 79.8 | I20: =F20*0.2+H20*0.5+G20*0.3 -> 84.286984
A21: 2022210359 | B21: 李宝航 | C21: 55 | D21: 63.333333 | E21: 0 | F21: =C21*0.2+D21*0.5+E21*0.3 -> 42.666667 | G21: 0 | H21: 78.99 | I21: =F21*0.2+H21*0.5+G21*0.3 -> 48.028333
A22: 2022210360 | B22: 李浩 | C22: 89 | D22: 75.555556 | E22: 90 | F22: =C22*0.2+D22*0.5+E22*0.3 -> 82.577778 | G22: 87.857143 | H22: 70.8 | I22: =F22*0.2+H22*0.5+G22*0.3 -> 78.272698
A23: 2022210361 | B23: 李今朝 | C23: 72 | D23: 76.666667 | E23: 94 | F23: =C23*0.2+D23*0.5+E23*0.3 -> 80.933333 | G23: 83.333333 | H23: 90.41 | I23: =F23*0.2+H23*0.5+G23*0.3 -> 86.391667
A24: 2022210362 | B24: 李良辰 | C24: 55 | D24: 81.111111 | E24: 90 | F24: =C24*0.2+D24*0.5+E24*0.3 -> 78.555556 | G24: 74.285714 | H24: 65.8 | I24: =F24*0.2+H24*0.5+G24*0.3 -> 70.896825
... A43: 2022210405 | B43: 张金龙 | C43: 89 | D43: 82.222222 | E43: 97 | F43: =C43*0.2+D43*0.5+E43*0.3 -> 88.011111 | G43: 84.285714 | H43: 81.6 | I43: =F43*0.2+H43*0.5+G43*0.3 -> 83.687937
A44: 2022210407 | B44: 张克 | C44: 0 | D44: 0 | E44: 72 | F44: =C44*0.2+D44*0.5+E44*0.3 -> 21.6 | G44: 0 | H44: 旷缺 | I44: 4
A45: 2022210411 | B45: 张文抱 | C45: 64 | D45: 84.444444 | E45: 99 | F45: =C45*0.2+D45*0.5+E45*0.3 -> 84.722222 | G45: 87.142857 | H45: 53 | I45: =F45*0.2+H45*0.5+G45*0.3 -> 69.587302
A46: 2022210414 | B46: 张玉妍 | C46: 72 | D46: 77.777778 | E46: 91 | F46: =C46*0.2+D46*0.5+E46*0.3 -> 80.588889 | G46: 85 | H46: 82.5 | I46: =F46*0.2+H46*0.5+G46*0.3 -> 82.867778
A47: 2022210416 | B47: 赵杰 | C47: 64 | D47: 80 | E47: 82 | F47: =C47*0.2+D47*0.5+E47*0.3 -> 77.4 | G47: 75.714286 | H47: 65.39 | I47: =F47*0.2+H47*0.5+G47*0.3 -> 70.889286
A48: 2022210417 | B48: 郑存耀 | C48: 55 | D48: 81.111111 | E48: 76 | F48: =C48*0.2+D48*0.5+E48*0.3 -> 74.355556 | G48: 85 | H48: 76.2 | I48: =F48*0.2+H48*0.5+G48*0.3 -> 78.471111
A49: 2022210422 | B49: 周宇 | C49: 81 | D49: 71.111111 | E49: 94 | F49: =C49*0.2+D49*0.5+E49*0.3 -> 79.955556 | G49: 82.857143 | H49: 76.21 | I49: =F49*0.2+H49*0.5+G49*0.3 -> 78.953254
A50: 2022210423 | B50: 朱传双 | C50: 81 | D50: 81.111111 | E50: 96 | F50: =C50*0.2+D50*0.5+E50*0.3 -> 85.555556 | G50: 85.714286 | H50: 58 | I50: =F50*0.2+H50*0.5+G50*0.3 -> 71.825397
A51: 2022210428 | B51: 朱世俊 | C51: 72 | D51: 61.111111 | E51: 78 | F51: =C51*0.2+D51*0.5+E51*0.3 -> 68.355556 | G51: 78.333333 | H51: 77.3 | I51: =F51*0.2+H51*0.5+G51*0.3 -> 75.821111
A52: 2022210429 | B52: 祝文耿 | C52: 89 | D52: 76.666667 | E52: 98 | F52: =C52*0.2+D52*0.5+E52*0.3 -> 85.533333 | G52: 80 | H52: 67.6 | I52: =F52*0.2+H52*0.5+G52*0.3 -> 74.906667
A53: 2022210430 | B53: 宗梦晴 | C53: 81 | D53: 80 | E53: 86 | F53: =C53*0.2+D53*0.5+E53*0.3 -> 82 | G53: 86.428571 | H53: 91.8 | I53: =F53*0.2+H53*0.5+G53*0.3 -> 88.228571
